<?xml version="1.0" ?>
<robot name="fr3" xmlns:xacro="http://www.ros.org/wiki/xacro">
  <link name="fr3_link0">
    <visual>
      <geometry>
        <mesh filename="meshes/visual/link0.dae"/>
      </geometry>
    </visual>
    <collision>
      <geometry>
        <mesh filename="meshes/collision/link0.obj"/>
      </geometry>
    </collision>
    <inertial>
      <!-- Estimated guesses from CAD -->
      <origin rpy="0 0 0" xyz="-0.041018 -0.00014 0.049974"/>
      <mass value="0.629769"/>  
      <inertia ixx="0.00315" ixy="8.2904e-7" ixz="0.0015" iyy="0.00388" iyz="8.2299e-6" izz="0.004285"/>
    </inertial>
  </link>
  <link name="fr3_link1">
    <visual>
      <geometry>
        <mesh filename="meshes/visual/link1.dae"/>
      </geometry>
    </visual>
    <collision>
      <geometry>
        <mesh filename="meshes/collision/link1.obj"/>
      </geometry>
    </collision>
    <inertial>
      <origin rpy="0 0 0" xyz="0.003875 0.002081 -0.04762"/>
      <mass value="4.970684"/>
      <inertia ixx="0.70337" ixy="-0.00013900" ixz="0.0067720" iyy="0.70661" iyz="0.019169" izz="0.0091170"/>
    </inertial>
  </link>
  <joint name="fr3_joint1" type="revolute">
    <origin rpy="0 0 0" xyz="0 0 0.333"/>
    <parent link="fr3_link0"/>
    <child link="fr3_link1"/>
    <axis xyz="0 0 1"/>
    <limit effort="87.0" lower="-2.7437" upper="2.7437" velocity="2.62"/>
    <safety_controller k_position="100.0" k_velocity="40.0" soft_lower_limit="-2.7437" soft_upper_limit="2.7437"/>
  </joint>
  <link name="fr3_link2">
    <visual>
      <geometry>
        <mesh filename="meshes/visual/link2.dae"/>
      </geometry>
    </visual>
    <collision>
      <geometry>
        <mesh filename="meshes/collision/link2.obj"/>
      </geometry>
    </collision>
    <inertial>
      <origin rpy="0 0 0" xyz=" -0.003141 -0.02872  0.003495"/>
      <mass value="0.646926"/>
      <inertia ixx="0.0079620" ixy="-3.9250e-3" ixz="1.0254e-02" iyy="2.8110e-02" iyz="7.0400e-04" izz="2.5995e-02"/>
    </inertial>
  </link>
   <joint name="fr3_joint2" type="revolute">
    <origin rpy="-1.570796326794897 0 0" xyz="0 0 0"/>
    <parent link="fr3_link1"/>
    <child link="fr3_link2"/>
    <axis xyz="0 0 1"/>
    <limit effort="87.0" lower="-1.7837" upper="1.7837" velocity="2.62"/>
    <safety_controller k_position="100.0" k_velocity="40.0" soft_lower_limit="-1.7837" soft_upper_limit="1.7837"/>
  </joint>
  <link name="fr3_link3">
    <visual>
      <geometry>
        <mesh filename="meshes/visual/link3.dae"/>
      </geometry>
    </visual>
    <collision>
      <geometry>
        <mesh filename="meshes/collision/link3.obj"/>
      </geometry>
    </collision>
    <inertial>
      <origin rpy="0 0 0" xyz="2.7518e-02 3.9252e-02 -6.6502e-02"/>
      <mass value="3.228604"/>
      <inertia ixx="3.7242e-02" ixy="-4.7610e-03" ixz="-1.1396e-02" iyy="3.6155e-02" iyz="-1.2805e-02" izz="1.0830e-02"/>
    </inertial>
  </link>
  <joint name="fr3_joint3" type="revolute">
    <origin rpy="1.570796326794897 0 0" xyz="0 -0.316 0"/>
    <parent link="fr3_link2"/>
    <child link="fr3_link3"/>
    <axis xyz="0 0 1"/>
    <limit effort="87.0" lower="-2.9007" upper="2.9007" velocity="2.62"/>
    <safety_controller k_position="100.0" k_velocity="40.0" soft_lower_limit="-2.9007" soft_upper_limit="2.9007"/>
    <dynamics D="1" K="7000" damping="0.003" friction="0.0" mu_coulomb="0" mu_viscous="16"/>
  </joint>
  <link name="fr3_link4">
    <visual>
      <geometry>
        <mesh filename="meshes/visual/link4.dae"/>
      </geometry>
    </visual>
    <collision>
      <geometry>
        <mesh filename="meshes/collision/link4.obj"/>
      </geometry>
    </collision>
    <inertial>
      <origin rpy="0 0 0" xyz="-5.317e-02 1.04419e-01 2.7454e-02"/>
      <mass value="3.587895"/>
      <inertia ixx="2.5853e-02" ixy="7.7960e-03" ixz="-1.3320e-03" iyy="1.9552e-02" iyz="8.6410e-03" izz="2.8323e-02"/>
    </inertial>
  </link>
   <joint name="fr3_joint4" type="revolute">
    <origin rpy="1.570796326794897 0 0" xyz="0.0825 0 0"/>
    <parent link="fr3_link3"/>
    <child link="fr3_link4"/>
    <axis xyz="0 0 1"/>
    <limit effort="87.0" lower="-3.0421" upper="-0.1518" velocity="2.62"/>
    <safety_controller k_position="100.0" k_velocity="40.0" soft_lower_limit="-3.0421" soft_upper_limit="-0.1518"/>
  </joint>
  <link name="fr3_link5">
    <visual>
      <geometry>
        <mesh filename="meshes/visual/link5.dae"/>
      </geometry>
    </visual>
    <collision>
      <geometry>
        <mesh filename="meshes/collision/link5.obj"/>
      </geometry>
    </collision>
    <inertial>
      <origin rpy="0 0 0" xyz="-1.1953e-02 4.1065e-02 -3.8437e-02"/>
      <mass value="1.225946"/>
      <inertia ixx="3.5549e-02" ixy="-2.1170e-03" ixz="-4.0370e-03" iyy="2.9474e-02" iyz="2.2900e-04" izz="8.6270e-03"/>
    </inertial>
  </link>
   <joint name="fr3_joint5" type="revolute">
    <origin rpy="-1.570796326794897 0 0" xyz="-0.0825 0.384 0"/>
    <parent link="fr3_link4"/>
    <child link="fr3_link5"/>
    <axis xyz="0 0 1"/>
    <limit effort="12.0" lower="-2.8065" upper="2.8065" velocity="5.26"/>
    <safety_controller k_position="100.0" k_velocity="40.0" soft_lower_limit="-2.8065" soft_upper_limit="2.8065"/>
    <dynamics D="1" K="7000" damping="0.003" friction="0.0" mu_coulomb="0" mu_viscous="16"/>
  </joint>
  <link name="fr3_link6">
    <visual>
      <geometry>
        <mesh filename="meshes/visual/link6.dae"/>
      </geometry>
    </visual>
    <collision>
      <geometry>
        <mesh filename="meshes/collision/link6.obj"/>
      </geometry>
    </collision>
    <inertial>
      <origin rpy="0 0 0" xyz="6.0149e-02 -1.4117e-02 -1.0517e-02"/>
      <mass value="1.666555"/>
      <inertia ixx="1.9640e-03" ixy="1.0900e-04" ixz="-1.1580e-03" iyy="4.3540e-03" iyz="3.4100e-04" izz="5.4330e-03"/>
    </inertial>
  </link>
  <joint name="fr3_joint6" type="revolute">
    <origin rpy="1.570796326794897 0 0" xyz="0 0 0"/>
    <parent link="fr3_link5"/>
    <child link="fr3_link6"/>
    <axis xyz="0 0 1"/>
    <limit effort="12.0" lower="0.5445" upper="4.5169" velocity="4.18"/>
    <safety_controller k_position="100.0" k_velocity="40.0" soft_lower_limit="0.5445" soft_upper_limit="4.5169"/>
    <dynamics D="1" K="7000" damping="0.003" friction="0.0" mu_coulomb="0" mu_viscous="16"/>
  </joint>
  <link name="fr3_link7">
    <visual>
      <geometry>
        <mesh filename="meshes/visual/link7.dae"/>
      </geometry>
    </visual>
    <collision>
      <geometry>
        <mesh filename="meshes/collision/link7.obj"/>
      </geometry>
    </collision>
    <inertial>
      <origin rpy="0 0 0" xyz="1.0517e-02 -4.252e-03 6.1597e-02"/>
      <mass value="7.35522e-01"/>
      <inertia ixx="1.2516e-02" ixy="-4.2800e-04" ixz="-1.1960e-03" iyy="1.0027e-02" iyz="-7.4100e-04" izz="4.8150e-03"/>
    </inertial>
  </link>
  <joint name="fr3_joint7" type="revolute">
    <origin rpy="1.570796326794897 0 0" xyz="0.088 0 0"/>
    <parent link="fr3_link6"/>
    <child link="fr3_link7"/>
    <axis xyz="0 0 1"/>
    <limit effort="12.0" lower="-3.0159" upper="3.0159" velocity="5.26"/>
    <safety_controller k_position="100.0" k_velocity="40.0" soft_lower_limit="-3.0159" soft_upper_limit="3.0159"/>
    <dynamics D="1" K="7000" damping="0.003" friction="0.0" mu_coulomb="0" mu_viscous="16"/>
  </joint>
  <joint name="fr3_hand_joint" type="fixed">
    <!--
    <parent link="fr3_link8"/>
    -->
    <parent link="fr3_link7"/>
    <child link="panda_hand"/>
    <origin rpy="0 0 -0.785398163397" xyz="0 0 0.106"/>
    <!--
    <origin rpy="0 0 -0.785398163397" xyz="0 0 0"/>
    -->
  </joint>
  <!-- to avoid changing code base currently use same name for gripper parts-->
  <link name="panda_hand">
        <visual>
            <geometry>
                <mesh filename="meshes/visual/handv2.dae"/>
            </geometry>
        </visual>
        <collision>
            <geometry>
                <mesh filename="meshes/collision/handv2-collision-acd.obj"/>
            </geometry>
        </collision>
        <inertial>
            <mass value="0.144"/>
            <origin rpy="0 0 0" xyz="0.0 0.0 0.076"/>
            <!-- <origin rpy="0 0 0" xyz="4.56355733e-06 1.37559474e-02 2.45973584e-02"/> -->
            <!-- <inertia ixx="0.001" ixy="0.0" ixz="0.0" iyy="0.0025" iyz="0.0" izz="0.0017"/> -->
            <inertia ixx="5.45762e-04" ixy="0" ixz="0" iyy="5.55862e-04" iyz="0" izz="3.2088e-05" />
        </inertial>
    </link>
    <link name="panda_leftfinger">
        <visual>
            <geometry>
                <mesh filename="meshes/visual/handv2-finger.dae"/>
            </geometry>
        </visual>
        <collision>
            <geometry>
                <mesh filename="meshes/collision/handv2-finger-collision.obj"/>
            </geometry>
        </collision>
    </link>
    <link name="panda_rightfinger">
        <visual>
            <geometry>
                <mesh filename="meshes/visual/handv2-finger.dae"/>
            </geometry>
        </visual>
        <collision>
            <geometry>
                <mesh filename="meshes/collision/handv2-finger-collision.obj"/>
            </geometry>
        </collision>
    </link>
     <link name="panda_tool"/>
  <joint name="panda_finger_joint1" type="fixed">
    <parent link="panda_hand"/>
    <child link="panda_leftfinger"/>
    <origin rpy="0 0 -1.57079632679" xyz="0.0225 0 0.17"/>
    <axis xyz="0 1 0"/>
    <dynamics damping="10.0"/>
    <!-- <limit effort="20" lower="0.0" upper="0.04" velocity="0.2"/> -->
  </joint>
  <joint name="panda_finger_joint2" type="fixed">
    <parent link="panda_hand"/>
    <child link="panda_rightfinger"/>
    <origin rpy="0 0 -1.57079632679" xyz="-0.0225 0 0.17"/>
    <axis xyz="0 -1 0"/>
    <dynamics damping="10.0"/>
    <limit effort="20" lower="0.0" upper="0.04" velocity="0.2"/>
  </joint>
  <joint name="panda_hand_tool_joint" type="fixed">
    <origin xyz="0 0 0.19" rpy="0 0 0" />
    <parent link="panda_hand" />
    <child link="panda_tool" />
  </joint>
</robot>
